.....................F............................F.E........
======================================================================
ERROR: test_datatypes_multi (acute.test_dbapi.TestTypesEmbedded)
----------------------------------------------------------------------
Traceback (most recent call last):
  File "/home2/kskuhlman/projects/acute-dbapi/acute/test_requires.py", line 122, in newfunc
    func(*arg, **kw)
  File "/home2/kskuhlman/projects/acute-dbapi/acute/test_dbapi.py", line 1090, in test_datatypes_multi
    self._insert(self.con, self.cs, table=self.table, data=data)
  File "/home2/kskuhlman/projects/acute-dbapi/acute/test_dbapi.py", line 218, in _insert
    cur.execute(stmt, data)
ProgrammingError: INSERT has more target columns than expressions

-------------------- >> begin captured stdout << ---------------------
Connect args: %s, kwarg: %s ([], {'dsn': 'host=localhost dbname=kskuhlman user=kskuhlman password=printer1'})
data.keys() ['date1', 'timestamp1', 'time1']
Statement base: insert into apitest_testtypes (date1, timestamp1, time1) values

--------------------- >> end captured stdout << ----------------------

======================================================================
FAIL: test_executemany (acute.test_dbapi.TestCursor)
----------------------------------------------------------------------
Traceback (most recent call last):
  File "/home2/kskuhlman/projects/acute-dbapi/acute/test_dbapi.py", line 684, in test_executemany
    'cursor.fetchall retrieved incorrect number of rows'
AssertionError: cursor.fetchall retrieved incorrect number of rows
-------------------- >> begin captured stdout << ---------------------
Connect args: %s, kwarg: %s ([], {'dsn': 'host=localhost dbname=kskuhlman user=kskuhlman password=printer1'})

--------------------- >> end captured stdout << ----------------------

======================================================================
FAIL: test_callproc (acute.test_dbapi.TestSQLProcs)
----------------------------------------------------------------------
Traceback (most recent call last):
  File "/home2/kskuhlman/projects/acute-dbapi/acute/test_requires.py", line 122, in newfunc
    func(*arg, **kw)
  File "/home2/kskuhlman/projects/acute-dbapi/acute/test_dbapi.py", line 1101, in test_callproc
    self.assertNotEqual(r, None)
AssertionError: None == None
-------------------- >> begin captured stdout << ---------------------
Connect args: %s, kwarg: %s ([], {'dsn': 'host=localhost dbname=kskuhlman user=kskuhlman password=printer1'})

--------------------- >> end captured stdout << ----------------------

----------------------------------------------------------------------
Ran 61 tests in 3.673s

FAILED (failures=2, errors=1)
