.EEEEE....E........E.F..............EEE..EEE........E..E.EE..
======================================================================
ERROR: Connection should fail using bogus database
----------------------------------------------------------------------
Traceback (most recent call last):
  File "/home2/kskuhlman/projects/acute-dbapi/acute/test_requires.py", line 127, in newfunc
    raise(Unsupported)
Unsupported: 
-------------------- >> begin captured stdout << ---------------------
Connect args: %s, kwarg: %s (['NonexistentDatabase'], {})

--------------------- >> end captured stdout << ----------------------

======================================================================
ERROR: Connection should fail using bogus password
----------------------------------------------------------------------
Traceback (most recent call last):
  File "/home2/kskuhlman/projects/acute-dbapi/acute/test_requires.py", line 127, in newfunc
    raise(Unsupported)
Unsupported: 
-------------------- >> begin captured stdout << ---------------------
Connect args: %s, kwarg: %s (['kskuhlman'], {})

--------------------- >> end captured stdout << ----------------------

======================================================================
ERROR: Connection should fail using bogus username
----------------------------------------------------------------------
Traceback (most recent call last):
  File "/home2/kskuhlman/projects/acute-dbapi/acute/test_requires.py", line 127, in newfunc
    raise(Unsupported)
Unsupported: 
-------------------- >> begin captured stdout << ---------------------
Connect args: %s, kwarg: %s (['kskuhlman'], {})

--------------------- >> end captured stdout << ----------------------

======================================================================
ERROR: Can't commit, execute, or close a closed connection
----------------------------------------------------------------------
Traceback (most recent call last):
  File "/home2/kskuhlman/projects/acute-dbapi/acute/test_requires.py", line 127, in newfunc
    raise(Unsupported)
Unsupported: 
-------------------- >> begin captured stdout << ---------------------
Connect args: %s, kwarg: %s (['kskuhlman'], {})

--------------------- >> end captured stdout << ----------------------

======================================================================
ERROR: Can't close a closed connection
----------------------------------------------------------------------
Traceback (most recent call last):
  File "/home2/kskuhlman/projects/acute-dbapi/acute/test_requires.py", line 127, in newfunc
    raise(Unsupported)
Unsupported: 
-------------------- >> begin captured stdout << ---------------------
Connect args: %s, kwarg: %s (['kskuhlman'], {})

--------------------- >> end captured stdout << ----------------------

======================================================================
ERROR: Connection should fail using blank password
----------------------------------------------------------------------
Traceback (most recent call last):
  File "/home2/kskuhlman/projects/acute-dbapi/acute/test_requires.py", line 127, in newfunc
    raise(Unsupported)
Unsupported: 
-------------------- >> begin captured stdout << ---------------------
Connect args: %s, kwarg: %s (['kskuhlman'], {})

--------------------- >> end captured stdout << ----------------------

======================================================================
ERROR: Fetch methods should raise Error if no query issued
----------------------------------------------------------------------
Traceback (most recent call last):
  File "/home2/kskuhlman/projects/acute-dbapi/acute/test_requires.py", line 127, in newfunc
    raise(Unsupported)
Unsupported: 
-------------------- >> begin captured stdout << ---------------------
Connect args: %s, kwarg: %s (['kskuhlman'], {})

--------------------- >> end captured stdout << ----------------------

======================================================================
ERROR: module.BINARY must be defined.
----------------------------------------------------------------------
Traceback (most recent call last):
  File "/home2/kskuhlman/projects/acute-dbapi/acute/test_requires.py", line 127, in newfunc
    raise(Unsupported)
Unsupported

======================================================================
ERROR: test_Binary (acute.test_dbapi.TestModule)
----------------------------------------------------------------------
Traceback (most recent call last):
  File "/home2/kskuhlman/projects/acute-dbapi/acute/test_requires.py", line 130, in newfunc
    raise(UnexpectedSuccess)
UnexpectedSuccess

======================================================================
ERROR: module.DATETIME must be defined.
----------------------------------------------------------------------
Traceback (most recent call last):
  File "/home2/kskuhlman/projects/acute-dbapi/acute/test_requires.py", line 127, in newfunc
    raise(Unsupported)
Unsupported

======================================================================
ERROR: module.NUMBER must be defined.
----------------------------------------------------------------------
Traceback (most recent call last):
  File "/home2/kskuhlman/projects/acute-dbapi/acute/test_requires.py", line 127, in newfunc
    raise(Unsupported)
Unsupported

======================================================================
ERROR: module.ROWID must be defined.
----------------------------------------------------------------------
Traceback (most recent call last):
  File "/home2/kskuhlman/projects/acute-dbapi/acute/test_requires.py", line 127, in newfunc
    raise(Unsupported)
Unsupported

======================================================================
ERROR: module.STRING must be defined
----------------------------------------------------------------------
Traceback (most recent call last):
  File "/home2/kskuhlman/projects/acute-dbapi/acute/test_requires.py", line 127, in newfunc
    raise(Unsupported)
Unsupported

======================================================================
ERROR: test_datatypes_multi (acute.test_dbapi.TestTypesEmbedded)
----------------------------------------------------------------------
Traceback (most recent call last):
  File "/home2/kskuhlman/projects/acute-dbapi/acute/test_requires.py", line 127, in newfunc
    raise(Unsupported)
Unsupported: 
-------------------- >> begin captured stdout << ---------------------
Connect args: %s, kwarg: %s (['kskuhlman'], {})
data.keys() ['date1', 'timestamp1', 'time1']
Statement base: insert into apitest_testtypes (date1, timestamp1, time1) values

--------------------- >> end captured stdout << ----------------------

======================================================================
ERROR: test_time_insert (acute.test_dbapi.TestTypesEmbedded)
----------------------------------------------------------------------
Traceback (most recent call last):
  File "/home2/kskuhlman/projects/acute-dbapi/acute/test_requires.py", line 127, in newfunc
    raise(Unsupported)
Unsupported: 
-------------------- >> begin captured stdout << ---------------------
Connect args: %s, kwarg: %s (['kskuhlman'], {})
data.keys() ['time1']
Statement base: insert into apitest_testtypes (time1) values

--------------------- >> end captured stdout << ----------------------

======================================================================
ERROR: test_time_insert_subsecond (acute.test_dbapi.TestTypesEmbedded)
----------------------------------------------------------------------
Traceback (most recent call last):
  File "/home2/kskuhlman/projects/acute-dbapi/acute/test_requires.py", line 127, in newfunc
    raise(Unsupported)
Unsupported: 
-------------------- >> begin captured stdout << ---------------------
Connect args: %s, kwarg: %s (['kskuhlman'], {})
data.keys() ['time1']
Statement base: insert into apitest_testtypes (time1) values

--------------------- >> end captured stdout << ----------------------

======================================================================
ERROR: test_time_insert_subsecond_string (acute.test_dbapi.TestTypesEmbedded)
----------------------------------------------------------------------
Traceback (most recent call last):
  File "/home2/kskuhlman/projects/acute-dbapi/acute/test_requires.py", line 130, in newfunc
    raise(UnexpectedSuccess)
UnexpectedSuccess: 
-------------------- >> begin captured stdout << ---------------------
Connect args: %s, kwarg: %s (['kskuhlman'], {})
data.keys() ['time1']
Statement base: insert into apitest_testtypes (time1) values

--------------------- >> end captured stdout << ----------------------

======================================================================
FAIL: test_executemany (acute.test_dbapi.TestCursor)
----------------------------------------------------------------------
Traceback (most recent call last):
  File "/home2/kskuhlman/projects/acute-dbapi/acute/test_dbapi.py", line 684, in test_executemany
    'cursor.fetchall retrieved incorrect number of rows'
AssertionError: cursor.fetchall retrieved incorrect number of rows
-------------------- >> begin captured stdout << ---------------------
Connect args: %s, kwarg: %s (['kskuhlman'], {})

--------------------- >> end captured stdout << ----------------------

----------------------------------------------------------------------
Ran 61 tests in 1.594s

FAILED (failures=1, errors=17)
